<?xml version="1.0" encoding="UTF-8"?>
<sdf version='1.10'>
  <model name='elm4'>
    <self_collide>false</self_collide>
    <static>false</static>
    <link name="base_link">
      <pose>0.0 0.0 0.15 0 0 0</pose>
      <inertial>
        <mass>18.71</mass>
        <inertia>
          <ixx>0.3986</ixx>
          <ixy>0</ixy>
          <ixz>0</ixz>
          <iyy>1.092</iyy>
          <iyz>0</iyz>
          <izz>1.337</izz>
        </inertia>
      </inertial>
      <gravity>true</gravity>
      <velocity_decay/>
      <collision name="Base_Collision">
        <pose>0 0 .0875 0 0 0</pose>
        <geometry>
          <box>
            <size>0.8 0.389 0.171</size>
          </box>
        </geometry>
        <surface>
          <contact>
            <ode>
              <min_depth>0.001</min_depth>
              <max_vel>0</max_vel>
            </ode>
          </contact>
        </surface>
      </collision>
      <visual name="BaseMetal">
        <pose>0 0 0 0 0 0</pose>
        <geometry>
          <mesh>
            <scale>1 1 1</scale>
            <uri>model://elm4/meshes/BaseMetal.dae</uri>
          </mesh>
        </geometry>
      </visual>
      <visual name="BaseRubber">
        <pose>0 0 0 0 0 0</pose>
        <geometry>
          <mesh>
            <scale>1 1 1</scale>
            <uri>model://elm4/meshes/BaseRubber.dae</uri>
          </mesh>
        </geometry>
      </visual>
      <visual name="BaseYellowPlasticTop">
        <pose>0 0 0 0 0 0</pose>
        <geometry>
          <mesh>
            <scale>1 1 1</scale>
            <uri>model://elm4/meshes/BasePlastic.dae</uri>
          </mesh>
        </geometry>
      </visual>
      <visual name="BaseClearPlasticGuard">
        <pose>0 0 0 0 0 0</pose>
        <cast_shadow>0</cast_shadow>
        <transparency>.5</transparency>
        <geometry>
          <mesh>
            <scale>1 1 1</scale>
            <uri>model://elm4/meshes/BaseClear.dae</uri>
          </mesh>
        </geometry>
        <material>
          <diffuse>0.6 0.6 0.7 1.0</diffuse>
          <ambient>0.6 0.6 0.7 1.0</ambient>
        </material>
      </visual>
    </link>
    <link name="base_footprint"/>
    <link name="rplidar_link">
      <pose relative_to="base_link">0 0 0.22 0 0 0</pose>
      <inertial>
        <mass>0.17</mass>
        <inertia>
          <ixx>0.0001926666667</ixx> <!-- (.17/12)*(.1^2+.06^2) -->
          <ixy>0</ixy>
          <ixz>0</ixz>
          <iyy>0.0001224141667</iyy> <!-- (.17/12)*(.071^2+.06^2) -->
          <iyz>0</iyz>
          <izz>0.0002130808333</izz> <!-- (.17/12)*(.071^2+.1^2) -->
        </inertia>
      </inertial>
      <visual name="visual">
        <geometry>
          <mesh>
            <uri>model://elm4/meshes/rplidar.dae</uri>
          </mesh>
        </geometry>
      </visual>
      <sensor name="rplidar" type="gpu_lidar">
        <lidar>
          <scan>
            <horizontal>
              <samples>400</samples>
              <resolution>1</resolution>
              <min_angle>-3.14159265359</min_angle>
              <max_angle>3.14159265359</max_angle>
            </horizontal>
          </scan>
          <range>
            <min>0.15</min>
            <max>12</max>
            <resolution>0.01</resolution>
          </range>
        </lidar>
        <gz_frame_id>rplidar_link</gz_frame_id>
        <alwaysOn>1</alwaysOn>
        <visualize>true</visualize>
        <update_rate>10</update_rate>
      </sensor>
    </link>
    <joint name="rplidar_joint" type="fixed">
      <parent>base_link</parent>
      <child>rplidar_link</child>
    </joint>
    <link name="sensors">
      <pose relative_to="base_link">0 0 0.22 0 0 0</pose>
      <inertial>
        <mass>0.0000001</mass>
        <inertia>
          <ixx>0.000000000001</ixx>
          <ixy>0</ixy>
          <ixz>0</ixz>
          <iyy>0.000000000001</iyy>
          <iyz>0</iyz>
          <izz>0.000000000001</izz>
        </inertia>
      </inertial>
      <sensor name="imu_sensor" type="imu">
        <always_on>1</always_on>
        <update_rate>250</update_rate>
      </sensor>
      <sensor name="mag_sensor" type="magnetometer">
        <always_on>1</always_on>
        <update_rate>50</update_rate>
      </sensor>
      <sensor name="altimeter_sensor" type="altimeter">
        <always_on>1</always_on>
        <update_rate>50</update_rate>
      </sensor>
      <sensor name="navsat_sensor" type="navsat">
        <always_on>1</always_on>
        <update_rate>10</update_rate>
        <navsat>
          <position_sensing></position_sensing>
          <velocity_sensing></velocity_sensing>
        </navsat>
      </sensor>
    </link>
    <link name="FrontLeftArm">
      <pose relative_to="FrontLeftArmJoint">0 0 0 0 0 0</pose>
      <inertial>
        <mass>1.16</mass>
        <inertia>
          <ixx>0.006274</ixx>
          <ixy>0.002744</ixy>
          <ixz>0</ixz>
          <iyy>0.007678</iyy>
          <iyz>0</iyz>
          <izz>0.009408</izz>
        </inertia>
      </inertial>
      <gravity>true</gravity>
      <velocity_decay/>
      <visual name="FrontLeftArmMetal_Visual">
        <pose>0 0 0 0 0 0</pose>
        <geometry>
          <mesh>
            <scale>1 1 1</scale>
            <uri>model://elm4/meshes/ArmLeftMetal.dae</uri>
          </mesh>
        </geometry>
      </visual>
      <visual name="FrontLeftArmPlastic_Visual">
        <pose>0 0 0 0 0 0</pose>
        <geometry>
          <mesh>
            <scale>1 1 1</scale>
            <uri>model://elm4/meshes/ArmLeftPlastic.dae</uri>
          </mesh>
        </geometry>
      </visual>
      <collision name="FrontLeftArm_Collision">
        <pose>0.055 0 -.0305 0 .505 0</pose>
        <geometry>
          <box>
            <size>.21 .075 .038</size>
          </box>
        </geometry>
        <surface>
          <contact>
            <ode>
              <min_depth>0.001</min_depth>
              <max_vel>0</max_vel>
            </ode>
          </contact>
        </surface>
      </collision>
    </link>
    <link name="FrontLeftHubMotorWheel">
      <pose relative_to="FrontLeftHubMotorWheelJoint">0 0 0 0 0 0</pose>
      <inertial>
        <mass>3.854</mass>
        <inertia>
          <ixx>0.009002</ixx>
          <ixy>0.0006021</ixy>
          <ixz>0</ixz>
          <iyy>0.01313</iyy>
          <iyz>0</iyz>
          <izz>0.009003</izz>
        </inertia>
      </inertial>
      <gravity>true</gravity>
      <velocity_decay/>
      <visual name="FrontLeftHubMotorWheelMetal_Visual">
        <pose>0 0 0 0 0 3.14159265359</pose>
        <geometry>
          <mesh>
            <scale>1 1 1</scale>
            <uri>model://elm4/meshes/HubMotor.dae</uri>
          </mesh>
        </geometry>
      </visual>
      <visual name="FrontLeftHubMotorWheelRubber_Visual">
        <pose>0 0 0 0 0 3.14159265359</pose>
        <geometry>
          <mesh>
            <scale>1 1 1</scale>
            <uri>model://elm4/meshes/RubberWheel.dae</uri>
          </mesh>
        </geometry>
      </visual>
      <collision name="FrontLeftHubMotorWheel_Collision">
        <pose>0 0 0 1.57079632679 0 0</pose>
        <geometry>
          <cylinder>
            <radius>.108</radius>
            <length>.06</length>
          </cylinder>
        </geometry>
        <surface>
          <contact>
            <ode>
              <min_depth>0.001</min_depth>
              <max_vel>0</max_vel>
            </ode>
          </contact>
          <friction>
            <ode>
              <mu>1.0</mu>
              <mu2>0.8</mu2>
              <fdir1>1 0 0</fdir1>
            </ode>
          </friction>
        </surface>
      </collision>
    </link>
    <joint name="FrontLeftArmJoint" type="revolute">
      <parent>base_link</parent>
      <child>FrontLeftArm</child>
      <pose relative_to="base_link">.263 .238 .029 0 0 0</pose>
      <axis>
        <xyz>0 1 0</xyz>
        <limit>
          <lower>-0.5</lower>
          <upper>0.5</upper>
        </limit>
        <dynamics>
          <spring_reference>0</spring_reference>
          <spring_stiffness>300</spring_stiffness>
        </dynamics>
      </axis>
    </joint>
    <joint name="FrontLeftHubMotorWheelJoint" type="revolute">
      <parent>FrontLeftArm</parent>
      <child>FrontLeftHubMotorWheel</child>
      <pose relative_to="FrontLeftArm">.11861 .095 -.07453 0 0 0</pose>
      <axis>
        <xyz>0 1 0</xyz>
        <limit>
          <lower>-1e+16</lower>
          <upper>1e+16</upper>
        </limit>
      </axis>
    </joint>
    <link name="BackRightArm">
      <pose relative_to="BackRightArmJoint">0 0 0 0 0 0</pose>
      <inertial>
        <mass>1.16</mass>
        <inertia>
          <ixx>0.006274</ixx>
          <ixy>0.002744</ixy>
          <ixz>0</ixz>
          <iyy>0.007678</iyy>
          <iyz>0</iyz>
          <izz>0.009408</izz>
        </inertia>
      </inertial>
      <gravity>true</gravity>
      <velocity_decay/>
      <visual name="BackRightArmMetal_Visual">
        <pose>0 0 0 0 0 0</pose>
        <geometry>
          <mesh>
            <scale>1 1 1</scale>
            <uri>model://elm4/meshes/ArmLeftMetal.dae</uri>
          </mesh>
        </geometry>
      </visual>
      <visual name="BackRightArmPlastic_Visual">
        <pose>0 0 0 0 0 0</pose>
        <geometry>
          <mesh>
            <scale>1 1 1</scale>
            <uri>model://elm4/meshes/ArmLeftPlastic.dae</uri>
          </mesh>
        </geometry>
      </visual>
      <collision name="BackRightArm_Collision">
        <pose>0.055 0 -.0305 0 .505 0</pose>
        <geometry>
          <box>
            <size>.21 .075 .038</size>
          </box>
        </geometry>
        <surface>
          <contact>
            <ode>
              <min_depth>0.001</min_depth>
              <max_vel>0</max_vel>
            </ode>
          </contact>
        </surface>
      </collision>
    </link>
    <link name="BackRightHubMotorWheel">
      <pose relative_to="BackRightHubMotorWheelJoint">0 0 0 0 0 0</pose>
      <inertial>
        <mass>3.854</mass>
        <inertia>
          <ixx>0.009002</ixx>
          <ixy>0.0006021</ixy>
          <ixz>0</ixz>
          <iyy>0.01313</iyy>
          <iyz>0</iyz>
          <izz>0.009003</izz>
        </inertia>
      </inertial>
      <gravity>true</gravity>
      <velocity_decay/>
      <visual name="BackRightHubMotorWheelMetal_Visual">
        <pose>0 0 0 0 0 0</pose>
        <geometry>
          <mesh>
            <scale>1 1 1</scale>
            <uri>model://elm4/meshes/HubMotor.dae</uri>
          </mesh>
        </geometry>
      </visual>
      <visual name="BackRightHubMotorWheelRubber_Visual">
        <pose>0 0 0 0 0 0</pose>
        <geometry>
          <mesh>
            <scale>1 1 1</scale>
            <uri>model://elm4/meshes/RubberWheel.dae</uri>
          </mesh>
        </geometry>
      </visual>
      <collision name="BackRightHubMotorWheel_Collision">
        <pose>0 0 0 1.57079632679 0 0</pose>
        <geometry>
          <cylinder>
            <radius>.108</radius>
            <length>.06</length>
          </cylinder>
        </geometry>
        <surface>
          <contact>
            <ode>
              <min_depth>0.001</min_depth>
              <max_vel>0</max_vel>
            </ode>
          </contact>
          <friction>
            <ode>
              <mu>1.0</mu>
              <mu2>0.8</mu2>
              <fdir1>1 0 0</fdir1>
            </ode>
          </friction>
        </surface>
      </collision>
    </link>
    <joint name="BackRightArmJoint" type="revolute">
      <parent>base_link</parent>
      <child>BackRightArm</child>
      <pose relative_to="base_link">-.263 -.238 .029 0 0 3.14159265359</pose>
      <axis>
        <xyz>0 1 0</xyz>
        <limit>
          <lower>-0.5</lower>
          <upper>0.5</upper>
        </limit>
        <dynamics>
          <spring_reference>0</spring_reference>
          <spring_stiffness>300</spring_stiffness>
        </dynamics>
      </axis>
    </joint>
    <joint name="BackRightHubMotorWheelJoint" type="revolute">
      <parent>BackRightArm</parent>
      <child>BackRightHubMotorWheel</child>
      <pose relative_to="BackRightArm">.11861 .095 -.07453 0 0 3.14159265359</pose>
      <axis>
        <xyz>0 1 0</xyz>
        <limit>
          <lower>-1e+16</lower>
          <upper>1e+16</upper>
        </limit>
      </axis>
    </joint>
    <link name="FrontRightArm">
      <pose relative_to="FrontRightArmJoint">0 0 0 0 0 0</pose>
      <inertial>
        <mass>1.16</mass>
        <inertia>
          <ixx>0.006274</ixx>
          <ixy>0.002744</ixy>
          <ixz>0</ixz>
          <iyy>0.007678</iyy>
          <iyz>0</iyz>
          <izz>0.009408</izz>
        </inertia>
      </inertial>
      <gravity>true</gravity>
      <velocity_decay/>
      <visual name="FrontRightArmMetal_Visual">
        <pose>0 0 0 0 -.017 0</pose>
        <geometry>
          <mesh>
            <scale>1 1 1</scale>
            <uri>model://elm4/meshes/ArmRightMetal.dae</uri>
          </mesh>
        </geometry>
      </visual>
      <visual name="FrontRightArmPlastic_Visual">
        <pose>0 0 0 0 -.017 0</pose>
        <geometry>
          <mesh>
            <scale>1 1 1</scale>
            <uri>model://elm4/meshes/ArmRightPlastic.dae</uri>
          </mesh>
        </geometry>
      </visual>
      <collision name="FrontRightArm_Collision">
        <pose>0.055 0 -.0305 0 .505 0</pose>
        <geometry>
          <box>
            <size>.21 .075 .038</size>
          </box>
        </geometry>
        <surface>
          <contact>
            <ode>
              <min_depth>0.001</min_depth>
              <max_vel>0</max_vel>
            </ode>
          </contact>
        </surface>
      </collision>
    </link>
    <link name="FrontRightHubMotorWheel">
      <pose relative_to="FrontRightHubMotorWheelJoint">0 0 0 0 0 0</pose>
      <inertial>
        <mass>3.854</mass>
        <inertia>
          <ixx>0.009002</ixx>
          <ixy>0.0006021</ixy>
          <ixz>0</ixz>
          <iyy>0.01313</iyy>
          <iyz>0</iyz>
          <izz>0.009003</izz>
        </inertia>
      </inertial>
      <gravity>true</gravity>
      <velocity_decay/>
      <visual name="FrontRightHubMotorWheelMetal_Visual">
        <pose>0 0 0 0 0 0</pose>
        <geometry>
          <mesh>
            <scale>1 1 1</scale>
            <uri>model://elm4/meshes/HubMotor.dae</uri>
          </mesh>
        </geometry>
      </visual>
      <visual name="FrontRightHubMotorWheelRubber_Visual">
        <pose>0 0 0 0 0 0</pose>
        <geometry>
          <mesh>
            <scale>1 1 1</scale>
            <uri>model://elm4/meshes/RubberWheel.dae</uri>
          </mesh>
        </geometry>
      </visual>
      <collision name="FrontRightHubMotorWheel_Collision">
        <pose>0 0 0 1.57079632679 0 0</pose>
        <geometry>
          <cylinder>
            <radius>.108</radius>
            <length>.06</length>
          </cylinder>
        </geometry>
        <surface>
          <contact>
            <ode>
              <min_depth>0.001</min_depth>
              <max_vel>0</max_vel>
            </ode>
          </contact>
          <friction>
            <ode>
              <mu>1.0</mu>
              <mu2>0.8</mu2>
              <fdir1>1 0 0</fdir1>
            </ode>
          </friction>
        </surface>
      </collision>
    </link>
    <joint name="FrontRightArmJoint" type="revolute">
      <parent>base_link</parent>
      <child>FrontRightArm</child>
      <pose relative_to="base_link">.263 -.238 .029 0 0 0</pose>
      <axis>
        <xyz>0 1 0</xyz>
        <limit>
          <lower>-0.5</lower>
          <upper>0.5</upper>
        </limit>
        <dynamics>
          <spring_reference>0</spring_reference>
          <spring_stiffness>300</spring_stiffness>
        </dynamics>
      </axis>
    </joint>
    <joint name="FrontRightHubMotorWheelJoint" type="revolute">
      <parent>FrontRightArm</parent>
      <child>FrontRightHubMotorWheel</child>
      <pose relative_to="FrontRightArm">.11861 -.095 -.07453 0 0 0</pose>
      <axis>
        <xyz>0 1 0</xyz>
        <limit>
          <lower>-1e+16</lower>
          <upper>1e+16</upper>
        </limit>
      </axis>
    </joint>
        <link name="BackLeftArm">
      <pose relative_to="BackLeftArmJoint">0 0 0 0 0 0</pose>
      <inertial>
        <mass>1.16</mass>
        <inertia>
          <ixx>0.006274</ixx>
          <ixy>0.002744</ixy>
          <ixz>0</ixz>
          <iyy>0.007678</iyy>
          <iyz>0</iyz>
          <izz>0.009408</izz>
        </inertia>
      </inertial>
      <gravity>true</gravity>
      <velocity_decay/>
      <visual name="BackLeftArmMetal_Visual">
        <pose>0 0 0 0 -.017 0</pose>
        <geometry>
          <mesh>
            <scale>1 1 1</scale>
            <uri>model://elm4/meshes/ArmRightMetal.dae</uri>
          </mesh>
        </geometry>
      </visual>
      <visual name="BackLeftArmPlastic_Visual">
        <pose>0 0 0 0 -.017 0</pose>
        <geometry>
          <mesh>
            <scale>1 1 1</scale>
            <uri>model://elm4/meshes/ArmRightPlastic.dae</uri>
          </mesh>
        </geometry>
      </visual>
      <collision name="BackLeftArm_Collision">
        <pose>0.055 0 -.0305 0 .505 0</pose>
        <geometry>
          <box>
            <size>.21 .075 .038</size>
          </box>
        </geometry>
        <surface>
          <contact>
            <ode>
              <min_depth>0.001</min_depth>
              <max_vel>0</max_vel>
            </ode>
          </contact>
        </surface>
      </collision>
    </link>
    <link name="BackLeftHubMotorWheel">
      <pose relative_to="BackLeftHubMotorWheelJoint">0 0 0 0 0 0</pose>
      <inertial>
        <mass>3.854</mass>
        <inertia>
          <ixx>0.009002</ixx>
          <ixy>0.0006021</ixy>
          <ixz>0</ixz>
          <iyy>0.01313</iyy>
          <iyz>0</iyz>
          <izz>0.009003</izz>
        </inertia>
      </inertial>
      <gravity>true</gravity>
      <velocity_decay/>
      <visual name="BackLeftHubMotorWheelMetal_Visual">
        <pose>0 0 0 0 0 3.14159265359</pose>
        <geometry>
          <mesh>
            <scale>1 1 1</scale>
            <uri>model://elm4/meshes/HubMotor.dae</uri>
          </mesh>
        </geometry>
      </visual>
      <visual name="BackLeftHubMotorWheelRubber_Visual">
        <pose>0 0 0 0 0 3.14159265359</pose>
        <geometry>
          <mesh>
            <scale>1 1 1</scale>
            <uri>model://elm4/meshes/RubberWheel.dae</uri>
          </mesh>
        </geometry>
      </visual>
      <collision name="BackLeftHubMotorWheel_Collision">
        <pose>0 0 0 1.57079632679 0 0</pose>
        <geometry>
          <cylinder>
            <radius>.108</radius>
            <length>.06</length>
          </cylinder>
        </geometry>
        <surface>
          <contact>
            <ode>
              <min_depth>0.001</min_depth>
              <max_vel>0</max_vel>
            </ode>
          </contact>
          <friction>
            <ode>
              <mu>1.0</mu>
              <mu2>0.8</mu2>
              <fdir1>1 0 0</fdir1>
            </ode>
          </friction>
        </surface>
      </collision>
    </link>
    <joint name="BackLeftArmJoint" type="revolute">
      <parent>base_link</parent>
      <child>BackLeftArm</child>
      <pose relative_to="base_link">-.263 .238 .029 0 0 3.14159265359</pose>
      <axis>
        <xyz>0 1 0</xyz>
        <limit>
          <lower>-0.5</lower>
          <upper>0.5</upper>
        </limit>
        <dynamics>
          <spring_reference>0</spring_reference>
          <spring_stiffness>300</spring_stiffness>
        </dynamics>
      </axis>
    </joint>
    <joint name="BackLeftHubMotorWheelJoint" type="revolute">
      <parent>BackLeftArm</parent>
      <child>BackLeftHubMotorWheel</child>
      <pose relative_to="BackLeftArm">.11861 -.095 -.07453 0 0 3.14159265359</pose>
      <axis>
        <xyz>0 1 0</xyz>
        <limit>
          <lower>-1e+16</lower>
          <upper>1e+16</upper>
        </limit>
      </axis>
    </joint>
    <joint name="base_joint" type="fixed">
      <parent>base_footprint</parent>
      <child>base_link</child>
      <pose>0.0 0.0 -.15 0 0 0</pose>
    </joint>
    <joint name="SensorsJoint" type="fixed">
        <parent>base_link</parent>
        <child>sensors</child>
        <pose>0.0 0.0 0.0 0 0 0</pose>
    </joint>
    <plugin
        filename="gz-sim-joint-controller-system"
        name="gz::sim::systems::JointController">
      <joint_name>BackRightHubMotorWheelJoint</joint_name>
      <!-- <sub_topic>rear_right</sub_topic> -->
      <use_actuator_msg>true</use_actuator_msg>
      <actuator_number>0</actuator_number>
    </plugin>
    <plugin
        filename="gz-sim-joint-controller-system"
        name="gz::sim::systems::JointController">
      <joint_name>BackLeftHubMotorWheelJoint</joint_name>
      <!-- <sub_topic>rear_left</sub_topic> -->
      <use_actuator_msg>true</use_actuator_msg>
      <actuator_number>1</actuator_number>
    </plugin>
    <plugin
        filename="gz-sim-joint-controller-system"
        name="gz::sim::systems::JointController">
      <joint_name>FrontLeftHubMotorWheelJoint</joint_name>
      <!-- <sub_topic>front_left</sub_topic> -->
      <use_actuator_msg>true</use_actuator_msg>
      <actuator_number>2</actuator_number>
    </plugin>
    <plugin
        filename="gz-sim-joint-controller-system"
        name="gz::sim::systems::JointController">
      <joint_name>FrontRightHubMotorWheelJoint</joint_name>
      <!-- <sub_topic>front_right</sub_topic> -->
      <use_actuator_msg>true</use_actuator_msg>
      <actuator_number>3</actuator_number>
    </plugin>
    <plugin
      filename="gz-sim-odometry-publisher-system"
      name="gz::sim::systems::OdometryPublisher">
      <xyz_offset>0 0 0</xyz_offset>
      <rpy_offset>0 0 0</rpy_offset>
      <gaussian_noise>0</gaussian_noise>
      <robot_base_frame>base_link</robot_base_frame>
      <dimensions>3</dimensions>
      <odom_publish_frequency>30</odom_publish_frequency>
      <odom_frame>odom</odom_frame>
    </plugin>
  </model>
</sdf>
