<sdf version='1.9'>
  <model name='MiniMando'>
    <pose>0 0 .5 0 0 0</pose>
    <self_collide>false</self_collide>
    <static>false</static>
    <link name="MiniMando/Base">
      <inertial>
        <mass>10.71</mass>
        <inertia>
          <ixx>0.6</ixx>
          <ixy>0</ixy>
          <ixz>0</ixz>
          <iyy>0.6</iyy>
          <iyz>0</iyz>
          <izz>0.6</izz>
        </inertia>
      </inertial>
      <gravity>true</gravity>
      <velocity_decay/>
      <collision name="MiniMando/Base_Collision">
        <pose>0 0 0 0 0 0</pose>
        <geometry>
          <box>
            <size>0.44 0.3 0.16</size>
          </box>
        </geometry>
        <surface>
          <contact>
            <ode>
              <min_depth>0.001</min_depth>
              <max_vel>0</max_vel>
            </ode>
          </contact>
        </surface>
      </collision>
      <collision name="MiniMando/Base_Top_Collision">
        <pose>0 0 .069 0 0 0</pose>
        <geometry>
          <box>
            <size>0.46 0.42 0.022</size>
          </box>
        </geometry>
        <surface>
          <contact>
            <ode>
              <min_depth>0.001</min_depth>
              <max_vel>0</max_vel>
            </ode>
          </contact>
        </surface>
      </collision>
      <visual name="MiniMando/BaseMetal">
        <pose>0 0 -.082 0 0 0</pose>
        <geometry>
          <mesh>
            <scale>1 1 1</scale>
            <uri>model://MiniMando/meshes/MiniMando.dae</uri>
          </mesh>
        </geometry>
      </visual>
    </link>
    <link name="MiniMando/FrontLeftHubMotorWheel">
      <pose relative_to="MiniMando/FrontLeftHubMotorWheelJoint">0 0 0 0 0 0</pose>
      <inertial>
        <mass>3.854</mass>
        <inertia>
          <ixx>0.009002</ixx>
          <ixy>0.0006021</ixy>
          <ixz>0</ixz>
          <iyy>0.01313</iyy>
          <iyz>0</iyz>
          <izz>0.009003</izz>
        </inertia>
      </inertial>
      <gravity>true</gravity>
      <velocity_decay/>
      <visual name="MiniMando/FrontLeftHubMotorWheelMetal_Visual">
        <pose>0 0 0 0 0 0</pose>
        <geometry>
          <mesh>
            <scale>1 1 1</scale>
            <uri>model://MiniMando/meshes/HubMotor.dae</uri>
          </mesh>
        </geometry>
      </visual>
      <visual name="MiniMando/FrontLeftHubMotorWheelRubber_Visual">
        <pose>0 0 0 0 0 0</pose>
        <geometry>
          <mesh>
            <scale>1 1 1</scale>
            <uri>model://MiniMando/meshes/RubberWheel.dae</uri>
          </mesh>
        </geometry>
      </visual>
      <collision name="MiniMando/FrontLeftHubMotorWheel_Collision">
        <pose>0 0 0 1.57079632679 0 0</pose>
        <geometry>
          <cylinder>
            <radius>.108</radius>
            <length>.06</length>
          </cylinder>
        </geometry>
        <surface>
          <contact>
            <ode>
              <min_depth>0.001</min_depth>
              <max_vel>0</max_vel>
            </ode>
          </contact>
          <friction>
            <ode>
              <mu>1.0</mu>
              <mu2>0.8</mu2>
              <fdir1>1 0 0</fdir1>
            </ode>
          </friction>
        </surface>
      </collision>
    </link>
    <joint name="MiniMando/FrontLeftHubMotorWheelJoint" type="revolute">
      <parent>MiniMando/Base</parent>
      <child>MiniMando/FrontLeftHubMotorWheel</child>
      <pose relative_to="MiniMando/Base">.14 .204 -.061 0 0 3.14159265359</pose>
      <axis>
        <xyz>0 1 0</xyz>
        <limit>
          <lower>-1e+16</lower>
          <upper>1e+16</upper>
        </limit>
        <use_parent_model_frame>1</use_parent_model_frame>
      </axis>
    </joint>
    <link name="MiniMando/BackRightHubMotorWheel">
      <pose relative_to="MiniMando/BackRightHubMotorWheelJoint">0 0 0 0 0 0</pose>
      <inertial>
        <mass>3.854</mass>
        <inertia>
          <ixx>0.009002</ixx>
          <ixy>0.0006021</ixy>
          <ixz>0</ixz>
          <iyy>0.01313</iyy>
          <iyz>0</iyz>
          <izz>0.009003</izz>
        </inertia>
      </inertial>
      <gravity>true</gravity>
      <velocity_decay/>
      <visual name="MiniMando/BackRightHubMotorWheelMetal_Visual">
        <pose>0 0 0 0 0 0</pose>
        <geometry>
          <mesh>
            <scale>1 1 1</scale>
            <uri>model://MiniMando/meshes/HubMotor.dae</uri>
          </mesh>
        </geometry>
      </visual>
      <visual name="MiniMando/BackRightHubMotorWheelRubber_Visual">
        <pose>0 0 0 0 0 0</pose>
        <geometry>
          <mesh>
            <scale>1 1 1</scale>
            <uri>model://MiniMando/meshes/RubberWheel.dae</uri>
          </mesh>
        </geometry>
      </visual>
      <collision name="MiniMando/BackRightHubMotorWheel_Collision">
        <pose>0 0 0 1.57079632679 0 0</pose>
        <geometry>
          <cylinder>
            <radius>.108</radius>
            <length>.06</length>
          </cylinder>
        </geometry>
        <surface>
          <contact>
            <ode>
              <min_depth>0.001</min_depth>
              <max_vel>0</max_vel>
            </ode>
          </contact>
          <friction>
            <ode>
              <mu>1.0</mu>
              <mu2>0.8</mu2>
              <fdir1>1 0 0</fdir1>
            </ode>
          </friction>
        </surface>
      </collision>
    </link>
    <joint name="MiniMando/BackRightHubMotorWheelJoint" type="revolute">
      <parent>MiniMando/Base</parent>
      <child>MiniMando/BackRightHubMotorWheel</child>
      <pose relative_to="MiniMando/Base">-.14 -.204 -.061 0 0 0</pose>
      <axis>
        <xyz>0 1 0</xyz>
        <limit>
          <lower>-1e+16</lower>
          <upper>1e+16</upper>
        </limit>
        <use_parent_model_frame>1</use_parent_model_frame>
      </axis>
    </joint>
    <link name="MiniMando/FrontRightHubMotorWheel">
      <pose relative_to="MiniMando/FrontRightHubMotorWheelJoint">0 0 0 0 0 0</pose>
      <inertial>
        <mass>3.854</mass>
        <inertia>
          <ixx>0.009002</ixx>
          <ixy>0.0006021</ixy>
          <ixz>0</ixz>
          <iyy>0.01313</iyy>
          <iyz>0</iyz>
          <izz>0.009003</izz>
        </inertia>
      </inertial>
      <gravity>true</gravity>
      <velocity_decay/>
      <visual name="MiniMando/FrontRightHubMotorWheelMetal_Visual">
        <pose>0 0 0 0 0 0</pose>
        <geometry>
          <mesh>
            <scale>1 1 1</scale>
            <uri>model://MiniMando/meshes/HubMotor.dae</uri>
          </mesh>
        </geometry>
      </visual>
      <visual name="MiniMando/FrontRightHubMotorWheelRubber_Visual">
        <pose>0 0 0 0 0 0</pose>
        <geometry>
          <mesh>
            <scale>1 1 1</scale>
            <uri>model://MiniMando/meshes/RubberWheel.dae</uri>
          </mesh>
        </geometry>
      </visual>
      <collision name="MiniMando/FrontRightHubMotorWheel_Collision">
        <pose>0 0 0 1.57079632679 0 0</pose>
        <geometry>
          <cylinder>
            <radius>.108</radius>
            <length>.06</length>
          </cylinder>
        </geometry>
        <surface>
          <contact>
            <ode>
              <min_depth>0.001</min_depth>
              <max_vel>0</max_vel>
            </ode>
          </contact>
          <friction>
            <ode>
              <mu>1.0</mu>
              <mu2>0.8</mu2>
              <fdir1>1 0 0</fdir1>
            </ode>
          </friction>
        </surface>
      </collision>
    </link>
    <joint name="MiniMando/FrontRightHubMotorWheelJoint" type="revolute">
      <parent>MiniMando/Base</parent>
      <child>MiniMando/FrontRightHubMotorWheel</child>
      <pose relative_to="MiniMando/Base">.14 -.204 -.061 0 0 0</pose>
      <axis>
        <xyz>0 1 0</xyz>
        <limit>
          <lower>-1e+16</lower>
          <upper>1e+16</upper>
        </limit>
        <use_parent_model_frame>1</use_parent_model_frame>
      </axis>
    </joint>
    <link name="MiniMando/BackLeftHubMotorWheel">
      <pose relative_to="MiniMando/BackLeftHubMotorWheelJoint">0 0 0 0 0 0</pose>
      <inertial>
        <mass>3.854</mass>
        <inertia>
          <ixx>0.009002</ixx>
          <ixy>0.0006021</ixy>
          <ixz>0</ixz>
          <iyy>0.01313</iyy>
          <iyz>0</iyz>
          <izz>0.009003</izz>
        </inertia>
      </inertial>
      <gravity>true</gravity>
      <velocity_decay/>
      <visual name="MiniMando/BackLeftHubMotorWheelMetal_Visual">
        <pose>0 0 0 0 0 0</pose>
        <geometry>
          <mesh>
            <scale>1 1 1</scale>
            <uri>model://MiniMando/meshes/HubMotor.dae</uri>
          </mesh>
        </geometry>
      </visual>
      <visual name="MiniMando/BackLeftHubMotorWheelRubber_Visual">
        <pose>0 0 0 0 0 0</pose>
        <geometry>
          <mesh>
            <scale>1 1 1</scale>
            <uri>model://MiniMando/meshes/RubberWheel.dae</uri>
          </mesh>
        </geometry>
      </visual>
      <collision name="MiniMando/BackLeftHubMotorWheel_Collision">
        <pose>0 0 0 1.57079632679 0 0</pose>
        <geometry>
          <cylinder>
            <radius>.108</radius>
            <length>.06</length>
          </cylinder>
        </geometry>
        <surface>
          <contact>
            <ode>
              <min_depth>0.001</min_depth>
              <max_vel>0</max_vel>
            </ode>
          </contact>
          <friction>
            <ode>
              <mu>1.0</mu>
              <mu2>0.8</mu2>
              <fdir1>1 0 0</fdir1>
            </ode>
          </friction>
        </surface>
      </collision>
    </link>
    <joint name="MiniMando/BackLeftHubMotorWheelJoint" type="revolute">
      <parent>MiniMando/Base</parent>
      <child>MiniMando/BackLeftHubMotorWheel</child>
      <pose relative_to="MiniMando/Base">-.14 .204 -.061 0 0 3.14159265359</pose>
      <axis>
        <xyz>0 1 0</xyz>
        <limit>
          <lower>-1e+16</lower>
          <upper>1e+16</upper>
        </limit>
        <use_parent_model_frame>1</use_parent_model_frame>
      </axis>
    </joint>
    <plugin
        filename="gz-sim-joint-controller-system"
        name="gz::sim::systems::JointController">
      <joint_name>MiniMando/BackRightHubMotorWheelJoint</joint_name>
      <sub_topic>rear_right</sub_topic>
    </plugin>
    <plugin
        filename="gz-sim-joint-controller-system"
        name="gz::sim::systems::JointController">
      <joint_name>MiniMando/BackLeftHubMotorWheelJoint</joint_name>
      <sub_topic>rear_left</sub_topic>
    </plugin>
    <plugin
        filename="gz-sim-joint-controller-system"
        name="gz::sim::systems::JointController">
      <joint_name>MiniMando/FrontLeftHubMotorWheelJoint</joint_name>
      <sub_topic>front_left</sub_topic>
    </plugin>
    <plugin
        filename="gz-sim-joint-controller-system"
        name="gz::sim::systems::JointController">
      <joint_name>MiniMando/FrontRightHubMotorWheelJoint</joint_name>
      <sub_topic>front_right</sub_topic>
    </plugin>
    <plugin
      filename="gz-sim-odometry-publisher-system"
      name="gz::sim::systems::OdometryPublisher">
      <odom_frame>map</odom_frame>
      <xyz_offset>0 0 0</xyz_offset>
      <rpy_offset>0 0 0</rpy_offset>
      <gaussian_noise>0</gaussian_noise>
      <dimensions>3</dimensions>
      <odom_publish_frequency>50</odom_publish_frequency>
    </plugin>
  </model>
</sdf>